- [异常](#异常)
  - [异常屏蔽](#异常屏蔽)


### 异常

```ascii
                     ┌───────────┐
                     │  Object   │
                     └───────────┘
                           ▲
                           │
                     ┌───────────┐
                     │ Throwable │
                     └───────────┘
                           ▲
                 ┌─────────┴─────────┐
                 │                   │
           ┌───────────┐       ┌───────────┐
           │   Error   │       │ Exception │
           └───────────┘       └───────────┘
                 ▲                   ▲
         ┌───────┘              ┌────┴──────────┐
         │                      │               │
┌─────────────────┐    ┌─────────────────┐┌───────────┐
│OutOfMemoryError │... │RuntimeException ││IOException│...
└─────────────────┘    └─────────────────┘└───────────┘
                                ▲
                    ┌───────────┴─────────────┐
                    │                         │
         ┌─────────────────────┐ ┌─────────────────────────┐
         │NullPointerException │ │IllegalArgumentException │...
         └─────────────────────┘ └─────────────────────────┘
```

```java
public class Main {
    public static void main(String[] args) {
        try {
            Integer.parseInt("abc");
        } catch (Exception e) {
            System.out.println("catched");
            throw new RuntimeException(e);
        } finally {
            System.out.println("finally");
        }
    }
}
```

上述代码执行结果如下：

```java
catched
finally
Exception in thread "main" java.lang.RuntimeException: java.lang.NumberFormatException: For input string: "abc"
    at Main.main(Main.java:8)
Caused by: java.lang.NumberFormatException: For input string: "abc"
    at ...
```

第一行打印了`catched`，说明进入了`catch`语句块。第二行打印了`finally`，说明执行了`finally`语句块。

因此，在`catch`中抛出异常，不会影响`finally`的执行。JVM会先执行`finally`，然后抛出异常。

#### 异常屏蔽

如果在执行`finally`语句时抛出异常，那么，`catch`语句的异常还能否继续抛出？例如：

```java
public class Main {
    public static void main(String[] args) {
        try {
            Integer.parseInt("abc");
        } catch (Exception e) {
            System.out.println("catched");
            throw new RuntimeException(e);
        } finally {
            System.out.println("finally");
            throw new IllegalArgumentException();
        }
    }
}
```

执行上述代码，发现异常信息如下：

```java
catched
finally
Exception in thread "main" java.lang.IllegalArgumentException
    at Main.main(Main.java:11)
```

这说明`finally`抛出异常后，原来在`catch`中准备抛出的异常就“消失”了，因为只能抛出一个异常。没有被抛出的异常称为“被屏蔽”的异常（Suppressed Exception）。





